{
 "cells": [
  {
   "cell_type": "code",
   "execution_count": 10,
   "metadata": {},
   "outputs": [],
   "source": [
    "from test import segmenta_img\n",
    "from keras.models import load_model\n",
    "from utils import dice_coef_loss, dice_coef, iou"
   ]
  },
  {
   "cell_type": "code",
   "execution_count": 9,
   "metadata": {},
   "outputs": [
    {
     "ename": "ValueError",
     "evalue": "Unknown loss function: dice_coef_loss. Please ensure this object is passed to the `custom_objects` argument. See https://www.tensorflow.org/guide/keras/save_and_serialize#registering_the_custom_object for details.",
     "output_type": "error",
     "traceback": [
      "\u001b[1;31m---------------------------------------------------------------------------\u001b[0m",
      "\u001b[1;31mValueError\u001b[0m                                Traceback (most recent call last)",
      "Cell \u001b[1;32mIn[9], line 1\u001b[0m\n\u001b[1;32m----> 1\u001b[0m loaded_model \u001b[39m=\u001b[39m load_model(\u001b[39mr\u001b[39;49m\u001b[39m\"\u001b[39;49m\u001b[39mC:\u001b[39;49m\u001b[39m\\\u001b[39;49m\u001b[39mUsers\u001b[39;49m\u001b[39m\\\u001b[39;49m\u001b[39mgkhay\u001b[39;49m\u001b[39m\\\u001b[39;49m\u001b[39mWorkstation\u001b[39;49m\u001b[39m\\\u001b[39;49m\u001b[39mmestrado\u001b[39;49m\u001b[39m\\\u001b[39;49m\u001b[39mPesquisa\u001b[39;49m\u001b[39m\\\u001b[39;49m\u001b[39mmacula_seg\u001b[39;49m\u001b[39m\\\u001b[39;49m\u001b[39mmodels\u001b[39;49m\u001b[39m\\\u001b[39;49m\u001b[39munet_dice.keras\u001b[39;49m\u001b[39m\"\u001b[39;49m)\n",
      "File \u001b[1;32mc:\\Users\\gkhay\\anaconda3\\envs\\tf_env\\lib\\site-packages\\keras\\utils\\traceback_utils.py:70\u001b[0m, in \u001b[0;36mfilter_traceback.<locals>.error_handler\u001b[1;34m(*args, **kwargs)\u001b[0m\n\u001b[0;32m     67\u001b[0m     filtered_tb \u001b[39m=\u001b[39m _process_traceback_frames(e\u001b[39m.\u001b[39m__traceback__)\n\u001b[0;32m     68\u001b[0m     \u001b[39m# To get the full stack trace, call:\u001b[39;00m\n\u001b[0;32m     69\u001b[0m     \u001b[39m# `tf.debugging.disable_traceback_filtering()`\u001b[39;00m\n\u001b[1;32m---> 70\u001b[0m     \u001b[39mraise\u001b[39;00m e\u001b[39m.\u001b[39mwith_traceback(filtered_tb) \u001b[39mfrom\u001b[39;00m \u001b[39mNone\u001b[39;00m\n\u001b[0;32m     71\u001b[0m \u001b[39mfinally\u001b[39;00m:\n\u001b[0;32m     72\u001b[0m     \u001b[39mdel\u001b[39;00m filtered_tb\n",
      "File \u001b[1;32mc:\\Users\\gkhay\\anaconda3\\envs\\tf_env\\lib\\site-packages\\keras\\utils\\generic_utils.py:769\u001b[0m, in \u001b[0;36mdeserialize_keras_object\u001b[1;34m(identifier, module_objects, custom_objects, printable_module_name)\u001b[0m\n\u001b[0;32m    767\u001b[0m     obj \u001b[39m=\u001b[39m module_objects\u001b[39m.\u001b[39mget(object_name)\n\u001b[0;32m    768\u001b[0m     \u001b[39mif\u001b[39;00m obj \u001b[39mis\u001b[39;00m \u001b[39mNone\u001b[39;00m:\n\u001b[1;32m--> 769\u001b[0m         \u001b[39mraise\u001b[39;00m \u001b[39mValueError\u001b[39;00m(\n\u001b[0;32m    770\u001b[0m             \u001b[39mf\u001b[39m\u001b[39m\"\u001b[39m\u001b[39mUnknown \u001b[39m\u001b[39m{\u001b[39;00mprintable_module_name\u001b[39m}\u001b[39;00m\u001b[39m: \u001b[39m\u001b[39m{\u001b[39;00mobject_name\u001b[39m}\u001b[39;00m\u001b[39m. Please \u001b[39m\u001b[39m\"\u001b[39m\n\u001b[0;32m    771\u001b[0m             \u001b[39m\"\u001b[39m\u001b[39mensure this object is passed to the `custom_objects` \u001b[39m\u001b[39m\"\u001b[39m\n\u001b[0;32m    772\u001b[0m             \u001b[39m\"\u001b[39m\u001b[39margument. See \u001b[39m\u001b[39m\"\u001b[39m\n\u001b[0;32m    773\u001b[0m             \u001b[39m\"\u001b[39m\u001b[39mhttps://www.tensorflow.org/guide/keras/save_and_serialize\u001b[39m\u001b[39m\"\u001b[39m\n\u001b[0;32m    774\u001b[0m             \u001b[39m\"\u001b[39m\u001b[39m#registering_the_custom_object for details.\u001b[39m\u001b[39m\"\u001b[39m\n\u001b[0;32m    775\u001b[0m         )\n\u001b[0;32m    777\u001b[0m \u001b[39m# Classes passed by name are instantiated with no args, functions are\u001b[39;00m\n\u001b[0;32m    778\u001b[0m \u001b[39m# returned as-is.\u001b[39;00m\n\u001b[0;32m    779\u001b[0m \u001b[39mif\u001b[39;00m tf_inspect\u001b[39m.\u001b[39misclass(obj):\n",
      "\u001b[1;31mValueError\u001b[0m: Unknown loss function: dice_coef_loss. Please ensure this object is passed to the `custom_objects` argument. See https://www.tensorflow.org/guide/keras/save_and_serialize#registering_the_custom_object for details."
     ]
    }
   ],
   "source": [
    "loaded_model = load_model(r\"C:\\Users\\gkhay\\Workstation\\mestrado\\Pesquisa\\macula_seg\\models\\unet_dice.keras\")"
   ]
  },
  {
   "cell_type": "code",
   "execution_count": null,
   "metadata": {},
   "outputs": [],
   "source": []
  }
 ],
 "metadata": {
  "kernelspec": {
   "display_name": "tf_env",
   "language": "python",
   "name": "python3"
  },
  "language_info": {
   "codemirror_mode": {
    "name": "ipython",
    "version": 3
   },
   "file_extension": ".py",
   "mimetype": "text/x-python",
   "name": "python",
   "nbconvert_exporter": "python",
   "pygments_lexer": "ipython3",
   "version": "3.10.12"
  },
  "orig_nbformat": 4
 },
 "nbformat": 4,
 "nbformat_minor": 2
}
